<?xml version='1.0'?>
<sdf version='1.6'>
		<model name="1-SRanger">
			<self_collide>true</self_collide>
			<pose>0.0 0.0 0.0 0.0 0.0 0.0</pose>
			<!-- Start of parts of the pmodel null::SRanger -->
			<!-- End of parts of the pmodel null::SRanger -->
			
			<!-- Start of links of the pmodel null::SRanger -->
			<!-- link full name is null::SRanger::Base -->
			<link name="2-Base">
					<pose>0.0 0.0 0.0 0.0 0.0 0.0</pose>
					<inertial>
						<pose>0.0 0.0 0.0 0.0 0.0 0.0</pose>
						<inertia>
							<ixx>1.0</ixx>
							<ixy>0.0</ixy>
							<ixz>0.0</ixz>
							<iyy>1.0</iyy>
							<iyz>0.0</iyz>
							<izz>1.0</izz>
						</inertia>
						<mass>1.0</mass>
					</inertial>
					<collision name="3-CasterWheel">
						<laser_retro>0.0</laser_retro>
						<pose>-0.0 0.0 -0.0 0.0 0.0 0.0</pose>
						<geometry>
						<sphere>
							<radius>0.0</radius>
						</sphere>
						</geometry>
						<surface>
							<bounce>
								<restitution_coefficient>0.0</restitution_coefficient>
								<threshold>100000.0</threshold>
							</bounce>
							<friction>
								<ode>
									<mu>1.0</mu>
									<mu2>1.0</mu2>
									<fdir1>0.0 0.0 0.0</fdir1>
									<slip1>0.0</slip1>
									<slip2>0.0</slip2>
								</ode>
								<torsional>
									<coefficient>1.0</coefficient>
									<surface_radius>0.0</surface_radius>
								</torsional>
							</friction>
						</surface>
					</collision>
					<visual name="3-CasterWheel">
						<laser_retro>0.0</laser_retro>
						<pose>-0.0 0.0 -0.0 0.0 0.0 0.0</pose>
						<geometry>
						<sphere>
							<radius>0.0</radius>
						</sphere>
						</geometry>
						<surface>
							<bounce>
								<restitution_coefficient>0.0</restitution_coefficient>
								<threshold>100000.0</threshold>
							</bounce>
							<friction>
								<ode>
									<mu>1.0</mu>
									<mu2>1.0</mu2>
									<fdir1>0.0 0.0 0.0</fdir1>
									<slip1>0.0</slip1>
									<slip2>0.0</slip2>
								</ode>
								<torsional>
									<coefficient>1.0</coefficient>
									<surface_radius>0.0</surface_radius>
								</torsional>
							</friction>
						</surface>
					</visual>
					<collision name="4-Chassis">
						<laser_retro>0.0</laser_retro>
						<pose>0.0 0.0 0.0 0.0 0.0 0.0</pose>
						<geometry>
						<box> 
							<size>0.0 0.0 0.0</size>
						</box>
						</geometry>
						<surface>
							<bounce>
								<restitution_coefficient>0.0</restitution_coefficient>
								<threshold>100000.0</threshold>
							</bounce>
							<friction>
								<ode>
									<mu>1.0</mu>
									<mu2>1.0</mu2>
									<fdir1>0.0 0.0 0.0</fdir1>
									<slip1>0.0</slip1>
									<slip2>0.0</slip2>
								</ode>
								<torsional>
									<coefficient>1.0</coefficient>
									<surface_radius>0.0</surface_radius>
								</torsional>
							</friction>
						</surface>
					</collision>
					<visual name="4-Chassis">
						<laser_retro>0.0</laser_retro>
						<pose>0.0 0.0 0.0 0.0 0.0 0.0</pose>
						<geometry>
						<box> 
							<size>0.0 0.0 0.0</size>
						</box>
						</geometry>
						<surface>
							<bounce>
								<restitution_coefficient>0.0</restitution_coefficient>
								<threshold>100000.0</threshold>
							</bounce>
							<friction>
								<ode>
									<mu>1.0</mu>
									<mu2>1.0</mu2>
									<fdir1>0.0 0.0 0.0</fdir1>
									<slip1>0.0</slip1>
									<slip2>0.0</slip2>
								</ode>
								<torsional>
									<coefficient>1.0</coefficient>
									<surface_radius>0.0</surface_radius>
								</torsional>
							</friction>
						</surface>
					</visual>
					<!-- WARNING: Annotation not found. The SDF generator relies on annotations to specify in SDF aspects
					     of the sensor that are accounted for in the equations. If you with to reflect these aspects in SDF,
					     please add an appropriate annotation to the sensor. --> 
			</link>	
			<!-- link full name is null::SRanger::LWheel -->
			<link name="5-LWheel">
					<pose>0.0 0.5 0.0 0.0 1.57075 1.57075</pose>
					<inertial>
						<pose>0.0 0.0 0.0 0.0 0.0 0.0</pose>
						<inertia>
							<ixx>1.0</ixx>
							<ixy>0.0</ixy>
							<ixz>0.0</ixz>
							<iyy>1.0</iyy>
							<iyz>0.0</iyz>
							<izz>1.0</izz>
						</inertia>
						<mass>1.0</mass>
					</inertial>
					<collision name="6-Wheel">
						<laser_retro>0.0</laser_retro>
						<pose>0.0 0.0 0.0 0.0 0.0 0.0</pose>
						<geometry>
						<cylinder>
							<radius>0.0</radius>
							<length>0.0</length>
						</cylinder>
						</geometry>
						<surface>
							<bounce>
								<restitution_coefficient>0.0</restitution_coefficient>
								<threshold>100000.0</threshold>
							</bounce>
							<friction>
								<ode>
									<mu>1.0</mu>
									<mu2>1.0</mu2>
									<fdir1>0.0 0.0 0.0</fdir1>
									<slip1>0.0</slip1>
									<slip2>0.0</slip2>
								</ode>
								<torsional>
									<coefficient>1.0</coefficient>
									<surface_radius>0.0</surface_radius>
								</torsional>
							</friction>
						</surface>
					</collision>
					<visual name="6-Wheel">
						<laser_retro>0.0</laser_retro>
						<pose>0.0 0.0 0.0 0.0 0.0 0.0</pose>
						<geometry>
						<cylinder>
							<radius>0.0</radius>
							<length>0.0</length>
						</cylinder>
						</geometry>
						<surface>
							<bounce>
								<restitution_coefficient>0.0</restitution_coefficient>
								<threshold>100000.0</threshold>
							</bounce>
							<friction>
								<ode>
									<mu>1.0</mu>
									<mu2>1.0</mu2>
									<fdir1>0.0 0.0 0.0</fdir1>
									<slip1>0.0</slip1>
									<slip2>0.0</slip2>
								</ode>
								<torsional>
									<coefficient>1.0</coefficient>
									<surface_radius>0.0</surface_radius>
								</torsional>
							</friction>
						</surface>
					</visual>
			</link>	
			<!-- link full name is null::SRanger::RWheel -->
			<link name="7-RWheel">
					<pose>0.0 -0.5 0.0 0.0 1.57075 1.57075</pose>
					<inertial>
						<pose>0.0 0.0 0.0 0.0 0.0 0.0</pose>
						<inertia>
							<ixx>1.0</ixx>
							<ixy>0.0</ixy>
							<ixz>0.0</ixz>
							<iyy>1.0</iyy>
							<iyz>0.0</iyz>
							<izz>1.0</izz>
						</inertia>
						<mass>1.0</mass>
					</inertial>
					<collision name="8-Wheel">
						<laser_retro>0.0</laser_retro>
						<pose>0.0 0.0 0.0 0.0 0.0 0.0</pose>
						<geometry>
						<cylinder>
							<radius>0.0</radius>
							<length>0.0</length>
						</cylinder>
						</geometry>
						<surface>
							<bounce>
								<restitution_coefficient>0.0</restitution_coefficient>
								<threshold>100000.0</threshold>
							</bounce>
							<friction>
								<ode>
									<mu>1.0</mu>
									<mu2>1.0</mu2>
									<fdir1>0.0 0.0 0.0</fdir1>
									<slip1>0.0</slip1>
									<slip2>0.0</slip2>
								</ode>
								<torsional>
									<coefficient>1.0</coefficient>
									<surface_radius>0.0</surface_radius>
								</torsional>
							</friction>
						</surface>
					</collision>
					<visual name="8-Wheel">
						<laser_retro>0.0</laser_retro>
						<pose>0.0 0.0 0.0 0.0 0.0 0.0</pose>
						<geometry>
						<cylinder>
							<radius>0.0</radius>
							<length>0.0</length>
						</cylinder>
						</geometry>
						<surface>
							<bounce>
								<restitution_coefficient>0.0</restitution_coefficient>
								<threshold>100000.0</threshold>
							</bounce>
							<friction>
								<ode>
									<mu>1.0</mu>
									<mu2>1.0</mu2>
									<fdir1>0.0 0.0 0.0</fdir1>
									<slip1>0.0</slip1>
									<slip2>0.0</slip2>
								</ode>
								<torsional>
									<coefficient>1.0</coefficient>
									<surface_radius>0.0</surface_radius>
								</torsional>
							</friction>
						</surface>
					</visual>
			</link>	
			<!-- End of links of the pmodel null::SRanger -->
			
			<!-- Start of joints of the pmodel null::SRanger -->
			<!-- Full name of joint: null::SRanger::Base::LHinge from null::SRanger::Base to null::SRanger::LWheel-->
			<joint name="9-LHinge" type="revolute">
				<pose>-2.3164352E-5 -2.3164352E-5 -0.5 1.57075 -4.6328703E-5 -1.5707964</pose>
				<parent>2-Base</parent>
				<child>5-LWheel</child>
				<!-- WARNING: Annotation not found. The SDF generator relies on annotations to specify in SDF aspects
				     of the joint that are accounted for in the equations. If you with to reflect these aspects in SDF,
				please add an appropriate annotation to the joint. --> 
				<!-- WARNING: Annotation not found in actuator. RoboSim actuators have no explicit counterparts in SDF, 
					 so the generator must rely on annotations to produce something meaningful in SDF. -->
			</joint>
			<!-- Full name of joint: null::SRanger::Base::RHinge from null::SRanger::Base to null::SRanger::RWheel-->
			<joint name="10-RHinge" type="revolute">
				<pose>2.3164352E-5 2.3164352E-5 0.5 1.57075 -4.6328703E-5 -1.5707964</pose>
				<parent>2-Base</parent>
				<child>7-RWheel</child>
				<!-- WARNING: Annotation not found. The SDF generator relies on annotations to specify in SDF aspects
				     of the joint that are accounted for in the equations. If you with to reflect these aspects in SDF,
				please add an appropriate annotation to the joint. --> 
				<!-- WARNING: Annotation not found in actuator. RoboSim actuators have no explicit counterparts in SDF, 
					 so the generator must rely on annotations to produce something meaningful in SDF. -->
			</joint>
			<!-- End of joints of the pmodel null::SRanger -->
			
			<!-- Start of fixed connections of the pmodel null::SRanger -->
			<!-- End of fixed connections of the pmodel null::SRanger -->
		</model>
</sdf>
